<?xml version="1.0" ?>
<!-- =================================================================================== -->
<!-- |                                This document is handwritten                     | -->
<!-- =================================================================================== -->
<robot name="yumi" xmlns:xacro="http://www.ros.org/wiki/xacro">
    <!-- ==================================== COLORS ======================================= -->
    <material name="Light_Grey">
        <color rgba="0.8 0.8 0.8 1.0" />
    </material>
    <material name="Black">
        <color rgba="0.0 0.0 0.0 1.0" />
    </material>
    <material name="Grey">
        <color rgba="0.5 0.5 0.5 1.0" />
    </material>
    <!-- =================================================================================== -->
    <!-- =================================================================================== -->
    <link name="world" />
    <!-- =================================================================================== -->
    <joint name="world_to_table" type="fixed">
        <parent link="world" />
        <child link="table" />
        <origin rpy="0 0 0" xyz="0 0 0" />
    </joint>
    <!-- =================================================================================== -->
    <link name="table">
        <visual>
            <origin rpy="0 0 0" xyz="0 0 0" />
            <geometry>
                <mesh filename="package://yumi_description/meshes/fuller/Table_M230382.stl" />
            </geometry>
            <material name="Grey" />
        </visual>
        <collision>
            <origin rpy="0 0 0" xyz="0 0 0" />
            <geometry>
                <mesh filename="package://yumi_description/meshes/fuller/Table_M230382.stl" />
            </geometry>
        </collision>
        <inertial>
            <mass value="0.1" />
            <origin xyz="0 0 0" rpy="0 0 0" />
            <inertia ixx="0.03" iyy="0.03" izz="0.03" ixy="0.0" ixz="0.0" iyz="0.0" />
        </inertial>
    </link>
    <!-- =================================================================================== -->
    <joint name="table_to_baselink" type="fixed">
        <parent link="table" />
        <child link="baselink" />
        <origin xyz="0 0 0.887" rpy="0 0 0" />
    </joint>
    <!-- =================================================================================== -->
    <link name="baselink" />
    <!-- =================================================================================== -->
    <joint name="baselink_to_body" type="fixed">
        <parent link="baselink" />
        <child link="body" />
        <origin rpy="0 0 0" xyz="0 0 0" />
    </joint>
    <!-- =================================================================================== -->
    <link name="body">
        <inertial>
            <origin rpy="0 0 0" xyz="0 0 0" />
            <mass value="15" />
            <inertia ixx="0.5" ixy="0" ixz="0" iyy="0.6" iyz="0" izz="0.3" />
        </inertial>
        <visual>
            <origin rpy="0 0 0" xyz="0 0 0" />
            <geometry>
                <mesh filename="package://yumi_description/meshes/fuller/body.stl" />
            </geometry>
            <material name="Light_Grey" />
        </visual>
        <collision>
            <origin rpy="0 0 0" xyz="0 0 0" />
            <geometry>
                <mesh filename="package://yumi_description/meshes/coarse/body.stl" />
            </geometry>
        </collision>
    </link>
    <!-- =================================================================================== -->
    <!-- |                                      RIGHT ARM                                  | -->
    <!-- =================================================================================== -->
    <joint name="body_to_R1" type="revolute">
        <parent link="body" />
        <child link="R1" />
        <origin rpy="-0.9795   -0.5682   -2.3155" xyz="0.05355 -0.0725 0.41492" />
        <axis xyz="0 0 1" />
        <limit effort="300" lower="-2.94087978961" upper="2.94087978961" velocity="3.14159265359" />
    </joint>
    <!-- =================================================================================== -->
    <link name="R1">
        <inertial>
            <origin rpy="0 0 0" xyz="0 -0.03 0.12" />
            <mass value="2" />
            <inertia ixx="0.1" ixy="0" ixz="0" iyy="0.1" iyz="0" izz="0.1" />
        </inertial>
        <visual>
            <origin rpy="0 0 0" xyz="0 0 0" />
            <geometry>
                <mesh filename="package://yumi_description/meshes/fuller/link_1.stl" />
            </geometry>
            <material name="Light_Grey" />
        </visual>
        <collision>
            <origin rpy="0 0 0" xyz="0 0 0" />
            <geometry>
                <mesh filename="package://yumi_description/meshes/coarse/link_1.stl" />
            </geometry>
        </collision>
    </link>
    <!-- =================================================================================== -->
    <joint name="R1_to_R2" type="revolute">
        <parent link="R1" />
        <child link="R2" />
        <origin rpy="1.57079632679 0.0 0.0" xyz="0.03 0.0 0.1" />
        <axis xyz="0 0 1" />
        <limit effort="300" lower="-2.50454747661" upper="0.759218224618" velocity="3.14159265359" />
    </joint>
    <!-- =================================================================================== -->
    <link name="R2">
        <inertial>
            <origin rpy="0 0 0" xyz="0 0 0" />
            <mass value="2" />
            <inertia ixx="0.1" ixy="0" ixz="0" iyy="0.1" iyz="0" izz="0.1" />
        </inertial>
        <visual>
            <origin rpy="0 0 0" xyz="0 0 0" />
            <geometry>
                <mesh filename="package://yumi_description/meshes/fuller/link_2.stl" />
            </geometry>
            <material name="Light_Grey" />
        </visual>
        <collision>
            <origin rpy="0 0 0" xyz="0 0 0" />
            <geometry>
                <mesh filename="package://yumi_description/meshes/coarse/link_2.stl" />
            </geometry>
        </collision>
    </link>
    <!-- =================================================================================== -->
    <joint name="R2_to_R3" type="revolute">
        <parent link="R2" />
        <child link="R3" />
        <origin rpy="-1.57079632679 0.0 0.0" xyz="-0.03 0.17283 0.0" />
        <axis xyz="0 0 1" />
        <limit effort="300" lower="-2.94087978961" upper="2.94087978961" velocity="3.14159265359" />
    </joint>
    <!-- =================================================================================== -->
    <link name="R3">
        <inertial>
            <origin rpy="0 0 0" xyz="0 0 0" />
            <mass value="2" />
            <inertia ixx="0.1" ixy="0" ixz="0" iyy="0.1" iyz="0" izz="0.1" />
        </inertial>
        <visual>
            <origin rpy="0 0 0" xyz="0 0 0" />
            <geometry>
                <mesh filename="package://yumi_description/meshes/fuller/link_3.stl" />
            </geometry>
            <material name="Light_Grey" />
        </visual>
        <collision>
            <origin rpy="0 0 0" xyz="0 0 0" />
            <geometry>
                <mesh filename="package://yumi_description/meshes/coarse/link_3.stl" />
            </geometry>
        </collision>
    </link>
    <!-- =================================================================================== -->
    <joint name="R3_to_R4" type="revolute">
        <parent link="R3" />
        <child link="R4" />
        <origin rpy="1.57079632679 -1.57079632679 0.0" xyz="-0.04188 0.0 0.07873" />
        <axis xyz="0 0 1" />
        <limit effort="300" lower="-2.15548162621" upper="1.3962634016" velocity="3.14159265359" />
    </joint>
    <!-- =================================================================================== -->
    <link name="R4">
        <inertial>
            <origin rpy="0 0 0" xyz="0 0 0" />
            <mass value="2" />
            <inertia ixx="0.1" ixy="0" ixz="0" iyy="0.1" iyz="0" izz="0.1" />
        </inertial>
        <visual>
            <origin rpy="0 0 0" xyz="0 0 0" />
            <geometry>
                <mesh filename="package://yumi_description/meshes/fuller/link_4.stl" />
            </geometry>
            <material name="Light_Grey" />
        </visual>
        <collision>
            <origin rpy="0 0 0" xyz="0 0 0" />
            <geometry>
                <mesh filename="package://yumi_description/meshes/coarse/link_4.stl" />
            </geometry>
        </collision>
    </link>
    <!-- =================================================================================== -->
    <joint name="R4_to_R5" type="revolute">
        <parent link="R4" />
        <child link="R5" />
        <origin rpy="-1.57079632679 0.0 0.0" xyz="0.0405 0.16461 0.0" />
        <axis xyz="0 0 1" />
        <limit effort="300" lower="-5.06145483078" upper="5.06145483078" velocity="6.98131700798" />
    </joint>
    <!-- =================================================================================== -->
    <link name="R5">
        <inertial>
            <origin rpy="0 0 0" xyz="0 0 0" />
            <mass value="2" />
            <inertia ixx="0.1" ixy="0" ixz="0" iyy="0.1" iyz="0" izz="0.1" />
        </inertial>
        <visual>
            <origin rpy="0 0 0" xyz="0 0 0" />
            <geometry>
                <mesh filename="package://yumi_description/meshes/fuller/link_5.stl" />
            </geometry>
            <material name="Light_Grey" />
        </visual>
        <collision>
            <origin rpy="0 0 0" xyz="0 0 0" />
            <geometry>
                <mesh filename="package://yumi_description/meshes/coarse/link_5.stl" />
            </geometry>
        </collision>
    </link>
    <!-- =================================================================================== -->
    <joint name="yumi_joint_5_r" type="revolute">
        <parent link="R5" />
        <child link="R6" />
        <origin rpy="1.57079632679 0.0 0.0" xyz="-0.027 0 0.10039" />
        <axis xyz="0 0 1" />
        <limit effort="300" lower="-1.53588974176" upper="2.40855436775" velocity="6.98131700798" />
    </joint>
    <!-- =================================================================================== -->
    <link name="R6">
        <inertial>
            <origin rpy="0 0 0" xyz="0 0 0" />
            <mass value="2" />
            <inertia ixx="0.1" ixy="0" ixz="0" iyy="0.1" iyz="0" izz="0.1" />
        </inertial>
        <visual>
            <origin rpy="0 0 0" xyz="0 0 0" />
            <geometry>
                <mesh filename="package://yumi_description/meshes/fuller/link_6.stl" />
            </geometry>
            <material name="Light_Grey" />
        </visual>
        <collision>
            <origin rpy="0 0 0" xyz="0 0 0" />
            <geometry>
                <mesh filename="package://yumi_description/meshes/coarse/link_6.stl" />
            </geometry>
        </collision>
    </link>
    <!-- =================================================================================== -->
    <joint name="yumi_joint_6_r" type="revolute">
        <parent link="R6" />
        <child link="R7" />
        <origin rpy="-1.57079632679 0.0 0.0" xyz="0.027 0.029 0.0" />
        <axis xyz="0 0 1" />
        <limit effort="300" lower="-3.99680398707" upper="3.99680398707" velocity="6.98131700798" />
    </joint>
    <!-- =================================================================================== -->
    <link name="R7">
        <inertial>
            <origin rpy="0 0 0" xyz="0 0 0" />
            <mass value="2" />
            <inertia ixx="0.1" ixy="0" ixz="0" iyy="0.1" iyz="0" izz="0.1" />
        </inertial>
        <visual>
            <origin rpy="0 0 0" xyz="0 0 0" />
            <geometry>
                <mesh filename="package://yumi_description/meshes/fuller/link_7.stl" />
            </geometry>
            <material name="Light_Grey" />
        </visual>
        <collision>
            <origin rpy="0 0 0" xyz="0 0 0" />
            <geometry>
                <mesh filename="package://yumi_description/meshes/coarse/link_7.stl" />
            </geometry>
        </collision>
    </link>
    <!-- =================================================================================== -->
    <!-- |                                  RIGHT GRIPPER                                  | -->
    <!-- =================================================================================== -->
    <joint name="R7_to_rightGripperBase" type="fixed">
        <origin rpy="0 0 3.14159265359" xyz="0 0 0.007" />
        <parent link="R7" />
        <child link="rightGripperBase" />
    </joint>
    <!-- =================================================================================== -->
    <link name="rightGripperBase">
        <inertial>
            <origin rpy="0 0 0" xyz="0 0 0" />
            <mass value="0.2" />
            <inertia ixx="0.0001" ixy="0" ixz="0" iyy="0.0001" iyz="0" izz="0.0001" />
        </inertial>
        <visual>
            <origin rpy="0 0 0" xyz="0 0 0" />
            <geometry>
                <mesh filename="package://yumi_description/meshes/fuller/gripperBase.stl" />
            </geometry>
            <material name="Light_Grey" />
        </visual>
        <collision>
            <origin rpy="0 0 0" xyz="0 0 0" />
            <geometry>
                <mesh filename="package://yumi_description/meshes/coarse/gripperBase.stl" />
            </geometry>
        </collision>
    </link>
    <!-- =================================================================================== -->
    <joint name="rightGripperBase_to_rightGripperR" type="prismatic">
        <parent link="rightGripperBase" />
        <child link="rightGripperR" />
        <origin rpy="0 0 0" xyz="0.002018 -0.001842 0.0837" />
        <axis xyz="-1 0 0" />
        <limit effort="20" lower="0" upper="0.025" velocity="2" />
    </joint>
    <!-- =================================================================================== -->
    <link name="rightGripperR">
        <inertial>
            <origin rpy="0 0 0" xyz="0 0 0" />
            <mass value="0.01" />
            <inertia ixx="0.000001" ixy="0" ixz="0" iyy="0.000001" iyz="0" izz="0.000001" />
        </inertial>
        <visual>
            <origin rpy="0 0 0" xyz="0 0 0" />
            <geometry>
                <mesh filename="package://yumi_description/meshes/fuller/yumiFingerV4.stl" />
            </geometry>
            <material name="Black" />
        </visual>
        <collision>
            <origin rpy="0 0 0" xyz="0 0 0" />
            <geometry>
                <mesh filename="package://yumi_description/meshes/coarse/yumiFingerV4.stl" />
            </geometry>
        </collision>
    </link>
    <!-- =================================================================================== -->
    <joint name="rightGripperBase_to_rightGripperL" type="prismatic">
        <parent link="rightGripperBase" />
        <child link="rightGripperL" />
        <origin rpy="0 0 3.14" xyz="-0.002018 0.001842 0.0837" />
        <axis xyz="-1 0 0" />
        <limit effort="20" lower="0" upper="0.025" velocity="2" />
        <mimic joint="rightGripperBase_to_rightGripperR" />
    </joint>
    <!-- =================================================================================== -->
    <link name="rightGripperL">
        <inertial>
            <origin rpy="0 0 0" xyz="0 0 0" />
            <mass value="0.01" />
            <inertia ixx="0.000001" ixy="0" ixz="0" iyy="0.000001" iyz="0" izz="0.000001" />
        </inertial>
        <visual>
            <origin rpy="0 0 0" xyz="0 0 0" />
            <geometry>
                <mesh filename="package://yumi_description/meshes/fuller/yumiFingerV4.stl" />
            </geometry>
            <material name="Black" />
        </visual>
        <collision>
            <origin rpy="0 0 0" xyz="0 0 0" />
            <geometry>
                <mesh filename="package://yumi_description/meshes/coarse/yumiFingerV4.stl" />
            </geometry>
        </collision>
    </link>
    <!-- =================================================================================== -->
    <!-- |                                       LEFT ARM                                  | -->
    <!-- =================================================================================== -->
    <joint name="body_to_L1" type="revolute">
        <parent link="body" />
        <child link="L1" />
        <origin rpy="0.9781 -0.5716 2.3180" xyz="0.05355 0.07250 0.41492" />
        <axis xyz="0 0 1" />
        <limit effort="300" lower="-2.94087978961" upper="2.94087978961" velocity="3.14159265359" />
    </joint>
    <!-- =================================================================================== -->
    <link name="L1">
        <inertial>
            <origin rpy="0 0 0" xyz="0 -0.03 0.12" />
            <mass value="2" />
            <inertia ixx="0.1" ixy="0" ixz="0" iyy="0.1" iyz="0" izz="0.1" />
        </inertial>
        <visual>
            <origin rpy="0 0 0" xyz="0 0 0" />
            <geometry>
                <mesh filename="package://yumi_description/meshes/fuller/link_1.stl" />
            </geometry>
            <material name="Light_Grey" />
        </visual>
        <collision>
            <origin rpy="0 0 0" xyz="0 0 0" />
            <geometry>
                <mesh filename="package://yumi_description/meshes/coarse/link_1.stl" />
            </geometry>
        </collision>
    </link>
    <!-- =================================================================================== -->
    <joint name="L1_to_L2" type="revolute">
        <parent link="L1" />
        <child link="L2" />
        <origin rpy="1.57079632679 0.0 0.0" xyz="0.03 0.0 0.1" />
        <axis xyz="0 0 1" />
        <limit effort="300" lower="-2.50454747661" upper="0.759218224618" velocity="3.14159265359" />
    </joint>
    <!-- =================================================================================== -->
    <link name="L2">
        <inertial>
            <origin rpy="0 0 0" xyz="0 0 0" />
            <mass value="2" />
            <inertia ixx="0.1" ixy="0" ixz="0" iyy="0.1" iyz="0" izz="0.1" />
        </inertial>
        <visual>
            <origin rpy="0 0 0" xyz="0 0 0" />
            <geometry>
                <mesh filename="package://yumi_description/meshes/fuller/link_2.stl" />
            </geometry>
            <material name="Light_Grey" />
        </visual>
        <collision>
            <origin rpy="0 0 0" xyz="0 0 0" />
            <geometry>
                <mesh filename="package://yumi_description/meshes/coarse/link_2.stl" />
            </geometry>
        </collision>
    </link>
    <!-- =================================================================================== -->
    <joint name="L2_to_L3" type="revolute">
        <parent link="L2" />
        <child link="L3" />
        <origin rpy="-1.57079632679 0.0 0.0" xyz="-0.03 0.17283 0.0" />
        <axis xyz="0 0 1" />
        <limit effort="300" lower="-2.94087978961" upper="2.94087978961" velocity="3.14159265359" />
    </joint>
    <!-- =================================================================================== -->
    <link name="L3">
        <inertial>
            <origin rpy="0 0 0" xyz="0 0 0" />
            <mass value="2" />
            <inertia ixx="0.1" ixy="0" ixz="0" iyy="0.1" iyz="0" izz="0.1" />
        </inertial>
        <visual>
            <origin rpy="0 0 0" xyz="0 0 0" />
            <geometry>
                <mesh filename="package://yumi_description/meshes/fuller/link_3.stl" />
            </geometry>
            <material name="Light_Grey" />
        </visual>
        <collision>
            <origin rpy="0 0 0" xyz="0 0 0" />
            <geometry>
                <mesh filename="package://yumi_description/meshes/coarse/link_3.stl" />
            </geometry>
        </collision>
    </link>
    <!-- =================================================================================== -->
    <joint name="L3_to_L4" type="revolute">
        <parent link="L3" />
        <child link="L4" />
        <origin rpy="1.57079632679 -1.57079632679 0.0" xyz="-0.04188 0.0 0.07873" />
        <axis xyz="0 0 1" />
        <limit effort="300" lower="-2.15548162621" upper="1.3962634016" velocity="3.14159265359" />
    </joint>
    <!-- =================================================================================== -->
    <link name="L4">
        <inertial>
            <origin rpy="0 0 0" xyz="0 0 0" />
            <mass value="2" />
            <inertia ixx="0.1" ixy="0" ixz="0" iyy="0.1" iyz="0" izz="0.1" />
        </inertial>
        <visual>
            <origin rpy="0 0 0" xyz="0 0 0" />
            <geometry>
                <mesh filename="package://yumi_description/meshes/fuller/link_4.stl" />
            </geometry>
            <material name="Light_Grey" />
        </visual>
        <collision>
            <origin rpy="0 0 0" xyz="0 0 0" />
            <geometry>
                <mesh filename="package://yumi_description/meshes/coarse/link_4.stl" />
            </geometry>
        </collision>
    </link>
    <!-- =================================================================================== -->
    <joint name="L4_to_L5" type="revolute">
        <parent link="L4" />
        <child link="L5" />
        <origin rpy="-1.57079632679 0.0 0.0" xyz="0.0405 0.16461 0.0" />
        <axis xyz="0 0 1" />
        <limit effort="300" lower="-5.06145483078" upper="5.06145483078" velocity="6.98131700798" />
    </joint>
    <!-- =================================================================================== -->
    <link name="L5">
        <inertial>
            <origin rpy="0 0 0" xyz="0 0 0" />
            <mass value="2" />
            <inertia ixx="0.1" ixy="0" ixz="0" iyy="0.1" iyz="0" izz="0.1" />
        </inertial>
        <visual>
            <origin rpy="0 0 0" xyz="0 0 0" />
            <geometry>
                <mesh filename="package://yumi_description/meshes/fuller/link_5.stl" />
            </geometry>
            <material name="Light_Grey" />
        </visual>
        <collision>
            <origin rpy="0 0 0" xyz="0 0 0" />
            <geometry>
                <mesh filename="package://yumi_description/meshes/coarse/link_5.stl" />
            </geometry>
        </collision>
    </link>
    <!-- =================================================================================== -->
    <joint name="L5_to_L6" type="revolute">
        <parent link="L5" />
        <child link="L6" />
        <origin rpy="1.57079632679 0.0 0.0" xyz="-0.027 0 0.10039" />
        <axis xyz="0 0 1" />
        <limit effort="300" lower="-1.53588974176" upper="2.40855436775" velocity="6.98131700798" />
    </joint>
    <!-- =================================================================================== -->
    <link name="L6">
        <inertial>
            <origin rpy="0 0 0" xyz="0 0 0" />
            <mass value="2" />
            <inertia ixx="0.1" ixy="0" ixz="0" iyy="0.1" iyz="0" izz="0.1" />
        </inertial>
        <visual>
            <origin rpy="0 0 0" xyz="0 0 0" />
            <geometry>
                <mesh filename="package://yumi_description/meshes/fuller/link_6.stl" />
            </geometry>
            <material name="Light_Grey" />
        </visual>
        <collision>
            <origin rpy="0 0 0" xyz="0 0 0" />
            <geometry>
                <mesh filename="package://yumi_description/meshes/coarse/link_6.stl" />
            </geometry>
        </collision>
    </link>
    <!-- =================================================================================== -->
    <joint name="L6_to_L7" type="revolute">
        <parent link="L6" />
        <child link="L7" />
        <origin rpy="-1.57079632679 0.0 0.0" xyz="0.027 0.029 0.0" />
        <axis xyz="0 0 1" />
        <limit effort="300" lower="-3.99680398707" upper="3.99680398707" velocity="6.98131700798" />
    </joint>
    <!-- =================================================================================== -->
    <link name="L7">
        <inertial>
            <origin rpy="0 0 0" xyz="0 0 0" />
            <mass value="2" />
            <inertia ixx="0.1" ixy="0" ixz="0" iyy="0.1" iyz="0" izz="0.1" />
        </inertial>
        <visual>
            <origin rpy="0 0 0" xyz="0 0 0" />
            <geometry>
                <mesh filename="package://yumi_description/meshes/fuller/link_7.stl" />
            </geometry>
            <material name="Light_Grey" />
        </visual>
        <collision>
            <origin rpy="0 0 0" xyz="0 0 0" />
            <geometry>
                <mesh filename="package://yumi_description/meshes/coarse/link_7.stl" />
            </geometry>
        </collision>
    </link>
    <!-- =================================================================================== -->
    <!-- |                                   LEFT GRIPPER                                  | -->
    <!-- =================================================================================== -->
    <joint name="L7_to_leftGripperBase" type="fixed">
        <origin rpy="0 0 3.14159265359" xyz="0 0 0.007" />
        <parent link="L7" />
        <child link="leftGripperBase" />
    </joint>
    <!-- =================================================================================== -->
    <link name="leftGripperBase">
        <inertial>
            <origin rpy="0 0 0" xyz="0 0 0" />
            <mass value="0.2" />
            <inertia ixx="0.0001" ixy="0" ixz="0" iyy="0.0001" iyz="0" izz="0.0001" />
        </inertial>
        <visual>
            <origin rpy="0 0 0" xyz="0 0 0" />
            <geometry>
                <mesh filename="package://yumi_description/meshes/fuller/gripperBase.stl" />
            </geometry>
            <material name="Light_Grey" />
        </visual>
        <collision>
            <origin rpy="0 0 0" xyz="0 0 0" />
            <geometry>
                <mesh filename="package://yumi_description/meshes/coarse/gripperBase.stl" />
            </geometry>
        </collision>
    </link>
    <!-- =================================================================================== -->
    <joint name="leftGripperBase_to_leftGripperR" type="prismatic">
        <parent link="leftGripperBase" />
        <child link="leftGripperR" />
        <origin rpy="0 0 0" xyz="0.002018 -0.001842 0.0837" />
        <axis xyz="-1 0 0" />
        <limit effort="20" lower="0" upper="0.025" velocity="2" />
    </joint>
    <!-- =================================================================================== -->
    <link name="leftGripperR">
        <inertial>
            <origin rpy="0 0 0" xyz="0 0 0" />
            <mass value="0.01" />
            <inertia ixx="0.000001" ixy="0" ixz="0" iyy="0.000001" iyz="0" izz="0.000001" />
        </inertial>
        <visual>
            <origin rpy="0 0 0" xyz="0 0 0" />
            <geometry>
                <mesh filename="package://yumi_description/meshes/fuller/yumiFingerV4.stl" />
            </geometry>
            <material name="Black" />
        </visual>
        <collision>
            <origin rpy="0 0 0" xyz="0 0 0" />
            <geometry>
                <mesh filename="package://yumi_description/meshes/coarse/yumiFingerV4.stl" />
            </geometry>
        </collision>
    </link>
    <!-- =================================================================================== -->
    <joint name="leftGripperBase_to_leftGripperL" type="prismatic">
        <parent link="leftGripperBase" />
        <child link="leftGripperL" />
        <origin rpy="0 0 3.14159265359" xyz="-0.002018 0.001842 0.0837" />
        <axis xyz="-1 0 0" />
        <limit effort="20" lower="0" upper="0.025" velocity="2" />
        <mimic joint="leftGripperBase_to_leftGripperR" />
    </joint>
    <!-- =================================================================================== -->
    <link name="leftGripperL">
        <inertial>
            <origin rpy="0 0 0" xyz="0 0 0" />
            <mass value="0.01" />
            <inertia ixx="0.000001" ixy="0" ixz="0" iyy="0.000001" iyz="0" izz="0.000001" />
        </inertial>
        <visual>
            <origin rpy="0 0 0" xyz="0 0 0" />
            <geometry>
                <mesh filename="package://yumi_description/meshes/fuller/yumiFingerV4.stl" />
            </geometry>
            <material name="Black" />
        </visual>
        <collision>
            <origin rpy="0 0 0" xyz="0 0 0" />
            <geometry>
                <mesh filename="package://yumi_description/meshes/coarse/yumiFingerV4.stl" />
            </geometry>
        </collision>
    </link>
    <!-- =================================================================================== -->
    <transmission name="trans_body_to_R1">
        <type>transmission_interface/SimpleTransmission</type>
        <joint name="body_to_R1">
            <hardwareInterface>hardware_interface/EffortJointInterface</hardwareInterface>
        </joint>
        <actuator name="body_to_R1_motor">
            <hardwareInterface>hardware_interface/EffortJointInterface</hardwareInterface>
            <mechanicalReduction>1</mechanicalReduction>
        </actuator>
    </transmission>
    <transmission name="trans_R1_to_R2">
        <type>transmission_interface/SimpleTransmission</type>
        <joint name="R1_to_R2">
            <hardwareInterface>hardware_interface/EffortJointInterface</hardwareInterface>
        </joint>
        <actuator name="R1_to_R2_motor">
            <hardwareInterface>hardware_interface/EffortJointInterface</hardwareInterface>
            <mechanicalReduction>1</mechanicalReduction>
        </actuator>
    </transmission>
    <transmission name="trans_R2_to_R3">
        <type>transmission_interface/SimpleTransmission</type>
        <joint name="R2_to_R3">
            <hardwareInterface>hardware_interface/EffortJointInterface</hardwareInterface>
        </joint>
        <actuator name="R2_to_R3_motor">
            <hardwareInterface>hardware_interface/EffortJointInterface</hardwareInterface>
            <mechanicalReduction>1</mechanicalReduction>
        </actuator>
    </transmission>
    <transmission name="trans_R3_to_R4">
        <type>transmission_interface/SimpleTransmission</type>
        <joint name="R3_to_R4">
            <hardwareInterface>hardware_interface/EffortJointInterface</hardwareInterface>
        </joint>
        <actuator name="R3_to_R4_motor">
            <hardwareInterface>hardware_interface/EffortJointInterface</hardwareInterface>
            <mechanicalReduction>1</mechanicalReduction>
        </actuator>
    </transmission>
    <transmission name="trans_R4_to_R5">
        <type>transmission_interface/SimpleTransmission</type>
        <joint name="R4_to_R5">
            <hardwareInterface>hardware_interface/EffortJointInterface</hardwareInterface>
        </joint>
        <actuator name="R4_to_R5_motor">
            <hardwareInterface>hardware_interface/EffortJointInterface</hardwareInterface>
            <mechanicalReduction>1</mechanicalReduction>
        </actuator>
    </transmission>
    <transmission name="trans_yumi_joint_5_r">
        <type>transmission_interface/SimpleTransmission</type>
        <joint name="yumi_joint_5_r">
            <hardwareInterface>hardware_interface/EffortJointInterface</hardwareInterface>
        </joint>
        <actuator name="yumi_joint_5_r_motor">
            <hardwareInterface>hardware_interface/EffortJointInterface</hardwareInterface>
            <mechanicalReduction>1</mechanicalReduction>
        </actuator>
    </transmission>
    <transmission name="trans_yumi_joint_6_r">
        <type>transmission_interface/SimpleTransmission</type>
        <joint name="yumi_joint_6_r">
            <hardwareInterface>hardware_interface/EffortJointInterface</hardwareInterface>
        </joint>
        <actuator name="yumi_joint_6_r_motor">
            <hardwareInterface>hardware_interface/EffortJointInterface</hardwareInterface>
            <mechanicalReduction>1</mechanicalReduction>
        </actuator>
    </transmission>
    <transmission name="trans_rightGripperBase_to_rightGripperR">
        <type>transmission_interface/SimpleTransmission</type>
        <joint name="rightGripperBase_to_rightGripperR">
            <hardwareInterface>hardware_interface/EffortJointInterface</hardwareInterface>
        </joint>
        <actuator name="rightGripperBase_to_rightGripperR_motor">
            <hardwareInterface>hardware_interface/EffortJointInterface</hardwareInterface>
            <mechanicalReduction>1</mechanicalReduction>
        </actuator>
    </transmission>
    <transmission name="trans_rightGripperBase_to_rightGripperL">
        <type>transmission_interface/SimpleTransmission</type>
        <joint name="rightGripperBase_to_rightGripperL">
            <hardwareInterface>hardware_interface/EffortJointInterface</hardwareInterface>
        </joint>
        <actuator name="rightGripperBase_to_rightGripperL_motor">
            <hardwareInterface>hardware_interface/EffortJointInterface</hardwareInterface>
            <mechanicalReduction>1</mechanicalReduction>
        </actuator>
    </transmission>
    <transmission name="trans_body_to_L1">
        <type>transmission_interface/SimpleTransmission</type>
        <joint name="body_to_L1">
            <hardwareInterface>hardware_interface/EffortJointInterface</hardwareInterface>
        </joint>
        <actuator name="body_to_L1_motor">
            <hardwareInterface>hardware_interface/EffortJointInterface</hardwareInterface>
            <mechanicalReduction>1</mechanicalReduction>
        </actuator>
    </transmission>
    <transmission name="trans_L1_to_L2">
        <type>transmission_interface/SimpleTransmission</type>
        <joint name="L1_to_L2">
            <hardwareInterface>hardware_interface/EffortJointInterface</hardwareInterface>
        </joint>
        <actuator name="L1_to_L2_motor">
            <hardwareInterface>hardware_interface/EffortJointInterface</hardwareInterface>
            <mechanicalReduction>1</mechanicalReduction>
        </actuator>
    </transmission>
    <transmission name="trans_L2_to_L3">
        <type>transmission_interface/SimpleTransmission</type>
        <joint name="L2_to_L3">
            <hardwareInterface>hardware_interface/EffortJointInterface</hardwareInterface>
        </joint>
        <actuator name="L2_to_L3_motor">
            <hardwareInterface>hardware_interface/EffortJointInterface</hardwareInterface>
            <mechanicalReduction>1</mechanicalReduction>
        </actuator>
    </transmission>
    <transmission name="trans_L3_to_L4">
        <type>transmission_interface/SimpleTransmission</type>
        <joint name="L3_to_L4">
            <hardwareInterface>hardware_interface/EffortJointInterface</hardwareInterface>
        </joint>
        <actuator name="L3_to_L4_motor">
            <hardwareInterface>hardware_interface/EffortJointInterface</hardwareInterface>
            <mechanicalReduction>1</mechanicalReduction>
        </actuator>
    </transmission>
    <transmission name="trans_L4_to_L5">
        <type>transmission_interface/SimpleTransmission</type>
        <joint name="L4_to_L5">
            <hardwareInterface>hardware_interface/EffortJointInterface</hardwareInterface>
        </joint>
        <actuator name="L4_to_L5_motor">
            <hardwareInterface>hardware_interface/EffortJointInterface</hardwareInterface>
            <mechanicalReduction>1</mechanicalReduction>
        </actuator>
    </transmission>
    <transmission name="trans_L5_to_L6">
        <type>transmission_interface/SimpleTransmission</type>
        <joint name="L5_to_L6">
            <hardwareInterface>hardware_interface/EffortJointInterface</hardwareInterface>
        </joint>
        <actuator name="L5_to_L6_motor">
            <hardwareInterface>hardware_interface/EffortJointInterface</hardwareInterface>
            <mechanicalReduction>1</mechanicalReduction>
        </actuator>
    </transmission>
    <transmission name="trans_L6_to_L7">
        <type>transmission_interface/SimpleTransmission</type>
        <joint name="L6_to_L7">
            <hardwareInterface>hardware_interface/EffortJointInterface</hardwareInterface>
        </joint>
        <actuator name="L6_to_L7_motor">
            <hardwareInterface>hardware_interface/EffortJointInterface</hardwareInterface>
            <mechanicalReduction>1</mechanicalReduction>
        </actuator>
    </transmission>
    <transmission name="trans_leftGripperBase_to_leftGripperR">
        <type>transmission_interface/SimpleTransmission</type>
        <joint name="leftGripperBase_to_leftGripperR">
            <hardwareInterface>hardware_interface/EffortJointInterface</hardwareInterface>
        </joint>
        <actuator name="leftGripperBase_to_leftGripperR_motor">
            <hardwareInterface>hardware_interface/EffortJointInterface</hardwareInterface>
            <mechanicalReduction>1</mechanicalReduction>
        </actuator>
    </transmission>
    <transmission name="trans_leftGripperBase_to_leftGripperL">
        <type>transmission_interface/SimpleTransmission</type>
        <joint name="leftGripperBase_to_leftGripperL">
            <hardwareInterface>hardware_interface/EffortJointInterface</hardwareInterface>
        </joint>
        <actuator name="leftGripperBase_to_leftGripperL_motor">
            <hardwareInterface>hardware_interface/EffortJointInterface</hardwareInterface>
            <mechanicalReduction>1</mechanicalReduction>
        </actuator>
    </transmission>
    <gazebo>
        <plugin name="gazebo_ros_control" filename="libgazebo_ros_control.so">
            <robotNamespace>/</robotNamespace>
        </plugin>
    </gazebo>
</robot>
